<?xml version="1.0" ?>
<!-- =================================================================================== -->
<!-- |    This document was autogenerated by xacro from robot_no_diff.urdf.xacro       | -->
<!-- |    EDITING THIS FILE BY HAND IS NOT RECOMMENDED                                 | -->
<!-- =================================================================================== -->
<robot name="SimpleMouse">
  <link name="base_link"/>
  <link name="body">
    <visual>
      <geometry>
        <box size="0.07 0.13 0.055"/>
      </geometry>
    </visual>
    <collision>
      <geometry>
        <box size="0.07 0.13 0.055"/>
      </geometry>
    </collision>
    <inertial>
      <origin rpy="0 0 0" xyz="0 0 0"/>
      <mass value="1.52"/>
      <inertia ixx="0.0025238333333333337" ixy="0" ixz="0" iyx="0" iyy="0.0010038333333333336" iyz="0" izx="0" izy="0" izz="0.002761333333333334"/>
    </inertial>
  </link>
  <joint name="body_joint" type="fixed">
    <parent link="base_link"/>
    <child link="body"/>
    <origin rpy="0 0 0" xyz="0 0 0.0275"/>
  </joint>
  <link name="wheel_r">
    <visual>
      <geometry>
        <cylinder length="0.008" radius="0.024"/>
      </geometry>
    </visual>
    <collision>
      <geometry>
        <cylinder length="0.008" radius="0.024"/>
      </geometry>
    </collision>
    <inertial>
      <origin rpy="0 0 0" xyz="0 0 0"/>
      <mass value="0.112"/>
      <inertia ixx="1.6725333333333337e-05" ixy="0" ixz="0" iyx="0" iyy="1.6725333333333337e-05" iyz="0" izx="0" izy="0" izz="3.2256000000000004e-05"/>
    </inertial>
  </link>
  <joint name="wheel_r_joint" type="continuous">
    <parent link="body"/>
    <child link="wheel_r"/>
    <origin rpy="0 1.570796326794895 0" xyz="0.04 0 -0.005500000000000001"/>
    <axis xyz="0 0 1"/>
    <limit effort="10" velocity="10"/>
    <joint_properties damping="0.0" friction="0.0"/>
  </joint>
  <link name="wheel_l">
    <visual>
      <geometry>
        <cylinder length="0.008" radius="0.024"/>
      </geometry>
    </visual>
    <collision>
      <geometry>
        <cylinder length="0.008" radius="0.024"/>
      </geometry>
    </collision>
    <inertial>
      <origin rpy="0 0 0" xyz="0 0 0"/>
      <mass value="0.112"/>
      <inertia ixx="1.6725333333333337e-05" ixy="0" ixz="0" iyx="0" iyy="1.6725333333333337e-05" iyz="0" izx="0" izy="0" izz="3.2256000000000004e-05"/>
    </inertial>
  </link>
  <joint name="wheel_l_joint" type="continuous">
    <parent link="body"/>
    <child link="wheel_l"/>
    <origin rpy="0 1.570796326794895 0" xyz="-0.04 0 -0.005500000000000001"/>
    <axis xyz="0 0 1"/>
    <limit effort="10" velocity="10"/>
    <joint_properties damping="0.0" friction="0.0"/>
  </joint>
  <link name="left_sensor">
    <visual>
      <geometry>
        <box size="0.01 0.005 0.005"/>
      </geometry>
    </visual>
    <inertial>
      <mass value="0.0001"/>
      <inertia ixx="0.00001" ixy="0" ixz="0" iyx="0" iyy="0.0001" iyz="0" izx="0" izy="0" izz="0.0001"/>
    </inertial>
  </link>
  <joint name="left_sensor_joint" type="fixed">
    <parent link="body"/>
    <child link="left_sensor"/>
    <origin rpy="0 0 0.5235987755982983" xyz="0.012 0.06 0.03"/>
  </joint>
  <gazebo reference="left_sensor">
    <sensor name="left_light_sensor" type="ray">
      <pose>0 0 0 0 0 0</pose>
      <visualize>true</visualize>
      <update_rate>20</update_rate>
      <ray>
        <scan>
          <horizontal>
            <samples>10</samples>
            <resolution>1</resolution>
            <min_angle> -0.09</min_angle>
            <max_angle>0.09</max_angle>
          </horizontal>
        </scan>
        <range>
          <min>0.01</min>
          <max>0.2</max>
          <resolution>0.001</resolution>
        </range>
        <noise>
          <type>gaussian</type>
          <mean>0.0</mean>
          <stddev>0.005</stddev>
        </noise>
      </ray>
      <plugin filename="libgazebo_ros_laser.so" name="gazebo_left_light_sensor_controller">
        <topicName>/light_sensor/left/scan</topicName>
        <frameName>left_sensor</frameName>
      </plugin>
    </sensor>
  </gazebo>
  <link name="right_sensor">
    <visual>
      <geometry>
        <box size="0.01 0.005 0.005"/>
      </geometry>
    </visual>
    <inertial>
      <mass value="0.0001"/>
      <inertia ixx="0.00001" ixy="0" ixz="0" iyx="0" iyy="0.0001" iyz="0" izx="0" izy="0" izz="0.0001"/>
    </inertial>
  </link>
  <joint name="right_sensor_joint" type="fixed">
    <parent link="body"/>
    <child link="right_sensor"/>
    <origin rpy="0 0 2.6179938779914917" xyz="-0.012 0.06 0.03"/>
  </joint>
  <gazebo reference="right_sensor">
    <sensor name="right_light_sensor" type="ray">
      <pose>0 0 0 0 0 0</pose>
      <visualize>true</visualize>
      <update_rate>20</update_rate>
      <ray>
        <scan>
          <horizontal>
            <samples>10</samples>
            <resolution>1</resolution>
            <min_angle> -0.09</min_angle>
            <max_angle>0.09</max_angle>
          </horizontal>
        </scan>
        <range>
          <min>0.01</min>
          <max>0.2</max>
          <resolution>0.001</resolution>
        </range>
        <noise>
          <type>gaussian</type>
          <mean>0.0</mean>
          <stddev>0.005</stddev>
        </noise>
      </ray>
      <plugin filename="libgazebo_ros_laser.so" name="gazebo_right_light_sensor_controller">
        <topicName>/light_sensor/right/scan</topicName>
        <frameName>right_sensor</frameName>
      </plugin>
    </sensor>
  </gazebo>
  <link name="front_left_sensor">
    <visual>
      <geometry>
        <box size="0.01 0.005 0.005"/>
      </geometry>
    </visual>
    <inertial>
      <mass value="0.0001"/>
      <inertia ixx="0.00001" ixy="0" ixz="0" iyx="0" iyy="0.0001" iyz="0" izx="0" izy="0" izz="0.0001"/>
    </inertial>
  </link>
  <joint name="front_left_sensor_joint" type="fixed">
    <parent link="body"/>
    <child link="front_left_sensor"/>
    <origin rpy="0 0 1.570796326794895" xyz="0.0325 0.04 0.03"/>
  </joint>
  <gazebo reference="front_left_sensor">
    <sensor name="front_left_light_sensor" type="ray">
      <pose>0 0 0 0 0 0</pose>
      <visualize>true</visualize>
      <update_rate>20</update_rate>
      <ray>
        <scan>
          <horizontal>
            <samples>10</samples>
            <resolution>1</resolution>
            <min_angle> -0.09</min_angle>
            <max_angle>0.09</max_angle>
          </horizontal>
        </scan>
        <range>
          <min>0.01</min>
          <max>0.2</max>
          <resolution>0.001</resolution>
        </range>
        <noise>
          <type>gaussian</type>
          <mean>0.0</mean>
          <stddev>0.005</stddev>
        </noise>
      </ray>
      <plugin filename="libgazebo_ros_laser.so" name="gazebo_front_left_light_sensor_controller">
        <topicName>/light_sensor/front_left/scan</topicName>
        <frameName>front_left_sensor</frameName>
      </plugin>
    </sensor>
  </gazebo>
  <link name="front_right_sensor">
    <visual>
      <geometry>
        <box size="0.01 0.005 0.005"/>
      </geometry>
    </visual>
    <inertial>
      <mass value="0.0001"/>
      <inertia ixx="0.00001" ixy="0" ixz="0" iyx="0" iyy="0.0001" iyz="0" izx="0" izy="0" izz="0.0001"/>
    </inertial>
  </link>
  <joint name="front_right_sensor_joint" type="fixed">
    <parent link="body"/>
    <child link="front_right_sensor"/>
    <origin rpy="0 0 1.570796326794895" xyz="-0.0325 0.04 0.03"/>
  </joint>
  <gazebo reference="front_right_sensor">
    <sensor name="front_right_light_sensor" type="ray">
      <pose>0 0 0 0 0 0</pose>
      <visualize>true</visualize>
      <update_rate>20</update_rate>
      <ray>
        <scan>
          <horizontal>
            <samples>10</samples>
            <resolution>1</resolution>
            <min_angle> -0.09</min_angle>
            <max_angle>0.09</max_angle>
          </horizontal>
        </scan>
        <range>
          <min>0.01</min>
          <max>0.2</max>
          <resolution>0.001</resolution>
        </range>
        <noise>
          <type>gaussian</type>
          <mean>0.0</mean>
          <stddev>0.005</stddev>
        </noise>
      </ray>
      <plugin filename="libgazebo_ros_laser.so" name="gazebo_front_right_light_sensor_controller">
        <topicName>/light_sensor/front_right/scan</topicName>
        <frameName>front_right_sensor</frameName>
      </plugin>
    </sensor>
  </gazebo>
  <gazebo>
    <plugin filename="libgazebo_ros_control.so" name="gazebo_ros_control">
      <robotNamespace>Raspimouse</robotNamespace>
    </plugin>
    <plugin filename="libgazebo_ros_p3d.so" name="ground_truth">
      <frameName>world</frameName>
      <bodyName>base_link</bodyName>
      <topicName>/tracker</topicName>
      <updateRate>10.0</updateRate>
    </plugin>
  </gazebo>
  <transmission name="trans1">
    <type>transmission_interface/SimpleTransmission</type>
    <joint name="wheel_r_joint">
      <hardwareInterface>VelocityJointInterface</hardwareInterface>
    </joint>
    <actuator name="wheel_r_motor">
      <hardwareInterface>VelocityJointInterface</hardwareInterface>
      <mechanismReduction>1</mechanismReduction>
    </actuator>
  </transmission>
  <transmission name="tran2">
    <type>transmission_interface/SimpleTransmission</type>
    <joint name="wheel_l_joint">
      <hardwareInterface>VelocityJointInterface</hardwareInterface>
    </joint>
    <actuator name="wheel_l_motor">
      <hardwareInterface>VelocityJointInterface</hardwareInterface>
      <mechanismReduction>1</mechanismReduction>
    </actuator>
  </transmission>
</robot>

